<?xml version="1.0" encoding="utf-8"?><testsuite errors="0" failures="0" name="pytest" skips="0" tests="13" time="2.114"><testcase classname="pytest_steps.tests.test_all" file="pytest_steps/tests/test_all.py" line="21" name="test_run_all_tests[test_steps_with_results_complex.py]" time="0.1137855052947998"><system-out>
Testing that running pytest on file test_steps_with_results_complex.py results in {&apos;skipped&apos;: 0, &apos;failed&apos;: 0, &apos;passed&apos;: 16}
============================= test session starts ==============================
platform linux -- Python 3.5.6, pytest-3.10.1, py-1.7.0, pluggy-0.8.0
rootdir: /tmp/pytest-of-travis/pytest-0/test_run_all_tests0, inifile:
plugins: metadata-1.7.0, html-1.19.0, harvest-1.0.0, faulthandler-1.5.0, cov-2.6.0
collected 16 items

test_run_all_tests.py ................                                   [100%]

========================== 16 passed in 0.06 seconds ===========================
</system-out></testcase><testcase classname="pytest_steps.tests.test_all" file="pytest_steps/tests/test_all.py" line="21" name="test_run_all_tests[test_steps_generator_does_not_change_order.py]" time="0.07185673713684082"><system-out>
Testing that running pytest on file test_steps_generator_does_not_change_order.py results in {&apos;skipped&apos;: 0, &apos;failed&apos;: 0, &apos;passed&apos;: 3}
============================= test session starts ==============================
platform linux -- Python 3.5.6, pytest-3.10.1, py-1.7.0, pluggy-0.8.0
rootdir: /tmp/pytest-of-travis/pytest-0/test_run_all_tests1, inifile:
plugins: metadata-1.7.0, html-1.19.0, harvest-1.0.0, faulthandler-1.5.0, cov-2.6.0
collected 3 items

test_run_all_tests.py ...                                                [100%]

=============================== warnings summary ===============================
test_run_all_tests.py::test_synthesis
  /home/travis/miniconda/envs/test-environment/lib/python3.5/site-packages/pytest_harvest/results_session.py:341: UserWarning: [pytest-harvest] Test items status is not available. You should maybe install pytest-harvest with pip. If it is already the case, you case try to force-use it by adding `pytest_plugins = [&apos;harvest&apos;]` to your conftest.py. But for normal use this should not be required, installing with pip should be enough.
    warn(&quot;[pytest-harvest] Test items status is not available. You should maybe install pytest-harvest with &quot;

-- Docs: https://docs.pytest.org/en/latest/warnings.html
===================== 3 passed, 1 warnings in 0.03 seconds =====================
</system-out></testcase><testcase classname="pytest_steps.tests.test_all" file="pytest_steps/tests/test_all.py" line="21" name="test_run_all_tests[test_wrapped_in_class.py]" time="0.0639336109161377"><system-out>
Testing that running pytest on file test_wrapped_in_class.py results in {&apos;skipped&apos;: 0, &apos;failed&apos;: 0, &apos;passed&apos;: 1}
============================= test session starts ==============================
platform linux -- Python 3.5.6, pytest-3.10.1, py-1.7.0, pluggy-0.8.0
rootdir: /tmp/pytest-of-travis/pytest-0/test_run_all_tests2, inifile:
plugins: metadata-1.7.0, html-1.19.0, harvest-1.0.0, faulthandler-1.5.0, cov-2.6.0
collected 1 item

test_run_all_tests.py .                                                  [100%]

=========================== 1 passed in 0.02 seconds ===========================
</system-out></testcase><testcase classname="pytest_steps.tests.test_all" file="pytest_steps/tests/test_all.py" line="21" name="test_run_all_tests[test_stackoverflow.py]" time="0.07005190849304199"><system-out>
Testing that running pytest on file test_stackoverflow.py results in {&apos;skipped&apos;: 0, &apos;failed&apos;: 0, &apos;passed&apos;: 3}
============================= test session starts ==============================
platform linux -- Python 3.5.6, pytest-3.10.1, py-1.7.0, pluggy-0.8.0
rootdir: /tmp/pytest-of-travis/pytest-0/test_run_all_tests3, inifile:
plugins: metadata-1.7.0, html-1.19.0, harvest-1.0.0, faulthandler-1.5.0, cov-2.6.0
collected 3 items

test_run_all_tests.py ...                                                [100%]

=========================== 3 passed in 0.02 seconds ===========================
</system-out></testcase><testcase classname="pytest_steps.tests.test_all" file="pytest_steps/tests/test_all.py" line="21" name="test_run_all_tests[test_steps_harvest.py]" time="0.5411884784698486"><system-out>
Testing that running pytest on file test_steps_harvest.py results in {&apos;skipped&apos;: 0, &apos;failed&apos;: 0, &apos;passed&apos;: 14}
============================= test session starts ==============================
platform linux -- Python 3.5.6, pytest-3.10.1, py-1.7.0, pluggy-0.8.0
rootdir: /tmp/pytest-of-travis/pytest-0/test_run_all_tests4, inifile:
plugins: metadata-1.7.0, html-1.19.0, harvest-1.0.0, faulthandler-1.5.0, cov-2.6.0
collected 14 items

test_run_all_tests.py ..............                                     [100%]

=============================== warnings summary ===============================
test_run_all_tests.py::test_synthesis
  /home/travis/miniconda/envs/test-environment/lib/python3.5/site-packages/pandas/core/reshape/merge.py:544: UserWarning: merging between different levels can give an unintended result (1 levels on the left, 2 on the right)
    warnings.warn(msg, UserWarning)

-- Docs: https://docs.pytest.org/en/latest/warnings.html
==================== 14 passed, 1 warnings in 0.49 seconds =====================
</system-out></testcase><testcase classname="pytest_steps.tests.test_all" file="pytest_steps/tests/test_all.py" line="21" name="test_run_all_tests[test_steps_new_with_generator.py]" time="0.18611383438110352"><system-out>
Testing that running pytest on file test_steps_new_with_generator.py results in {&apos;skipped&apos;: 2, &apos;failed&apos;: 2, &apos;passed&apos;: 12}
============================= test session starts ==============================
platform linux -- Python 3.5.6, pytest-3.10.1, py-1.7.0, pluggy-0.8.0
rootdir: /tmp/pytest-of-travis/pytest-0/test_run_all_tests5, inifile:
plugins: metadata-1.7.0, html-1.19.0, harvest-1.0.0, faulthandler-1.5.0, cov-2.6.0
collected 16 items

test_run_all_tests.py ....Fs.Fs.......                                   [100%]

=================================== FAILURES ===================================
________________ test_suite_exception_on_mandatory_step[step_b] ________________

________step_name_ = &apos;step_b&apos;
request = &lt;FixtureRequest for &lt;Function &apos;test_suite_exception_on_mandatory_step[step_b]&apos;&gt;&gt;

&gt;   ???

&lt;decorator-gen-8&gt;:2: 
_ _ _ _ _ _ _ _ _ _ _ _ _ _ _ _ _ _ _ _ _ _ _ _ _ _ _ _ _ _ _ _ _ _ _ _ _ _ _ _ 
/home/travis/build/smarie/python-pytest-steps/pytest_steps/decorator_hack.py:167: in caller
    **kwargs)
/home/travis/build/smarie/python-pytest-steps/pytest_steps/steps_generator.py:431: in step_function_wrapper
    steps_monitor.execute(step_name, *args, **kwargs)
/home/travis/build/smarie/python-pytest-steps/pytest_steps/steps_generator.py:270: in execute
    res = next(self.gen)
_ _ _ _ _ _ _ _ _ _ _ _ _ _ _ _ _ _ _ _ _ _ _ _ _ _ _ _ _ _ _ _ _ _ _ _ _ _ _ _ 

    @test_steps(&apos;step_a&apos;, &apos;step_b&apos;, &apos;step_c&apos;)
    def test_suite_exception_on_mandatory_step():
        &quot;&quot;&quot; &quot;&quot;&quot;
    
        # Step A
        print(&quot;step a&quot;)
        assert not False  # replace with your logic
        yield &apos;step_a&apos;
    
        # Step B
        print(&quot;step b&quot;)
&gt;       assert False  # replace with your logic
E       assert False

test_run_all_tests.py:43: AssertionError
----------------------------- Captured stdout call -----------------------------
step b
_______________ test_suite_optional_and_dependent_steps[step_b] ________________

________step_name_ = &apos;step_b&apos;
request = &lt;FixtureRequest for &lt;Function &apos;test_suite_optional_and_dependent_steps[step_b]&apos;&gt;&gt;

&gt;   ???

&lt;decorator-gen-9&gt;:2: 
_ _ _ _ _ _ _ _ _ _ _ _ _ _ _ _ _ _ _ _ _ _ _ _ _ _ _ _ _ _ _ _ _ _ _ _ _ _ _ _ 
/home/travis/build/smarie/python-pytest-steps/pytest_steps/decorator_hack.py:167: in caller
    **kwargs)
/home/travis/build/smarie/python-pytest-steps/pytest_steps/steps_generator.py:431: in step_function_wrapper
    steps_monitor.execute(step_name, *args, **kwargs)
/home/travis/build/smarie/python-pytest-steps/pytest_steps/steps_generator.py:292: in execute
    raise six.reraise(res.exec_result.exc_type, res.exec_result.exc_val, res.exec_result.tb)
/home/travis/miniconda/envs/test-environment/lib/python3.5/site-packages/six.py:693: in reraise
    raise value
_ _ _ _ _ _ _ _ _ _ _ _ _ _ _ _ _ _ _ _ _ _ _ _ _ _ _ _ _ _ _ _ _ _ _ _ _ _ _ _ 

    @test_steps(&apos;step_a&apos;, &apos;step_b&apos;, &apos;step_c&apos;, &apos;step_d&apos;)
    def test_suite_optional_and_dependent_steps():
        &quot;&quot;&quot; &quot;&quot;&quot;
    
        # Step A
        print(&quot;step a&quot;)
        assert not False
        yield &apos;step_a&apos;
    
        # Step B
        with optional_step(&apos;step_b&apos;) as step_b:
            print(&quot;step b&quot;)
&gt;           assert False
E           assert False

test_run_all_tests.py:64: AssertionError
----------------------------- Captured stdout call -----------------------------
step b
================ 2 failed, 12 passed, 2 skipped in 0.14 seconds ================
</system-out></testcase><testcase classname="pytest_steps.tests.test_all" file="pytest_steps/tests/test_all.py" line="21" name="test_run_all_tests[test_pytest_capabilities.py]" time="0.10396242141723633"><system-out>
Testing that running pytest on file test_pytest_capabilities.py results in {&apos;skipped&apos;: 0, &apos;failed&apos;: 0, &apos;passed&apos;: 16}
============================= test session starts ==============================
platform linux -- Python 3.5.6, pytest-3.10.1, py-1.7.0, pluggy-0.8.0
rootdir: /tmp/pytest-of-travis/pytest-0/test_run_all_tests6, inifile:
plugins: metadata-1.7.0, html-1.19.0, harvest-1.0.0, faulthandler-1.5.0, cov-2.6.0
collected 16 items

test_run_all_tests.py ................                                   [100%]

========================== 16 passed in 0.06 seconds ===========================
</system-out></testcase><testcase classname="pytest_steps.tests.test_all" file="pytest_steps/tests/test_all.py" line="21" name="test_run_all_tests[test_steps_with_results_basic.py]" time="0.07767558097839355"><system-out>
Testing that running pytest on file test_steps_with_results_basic.py results in {&apos;skipped&apos;: 0, &apos;failed&apos;: 0, &apos;passed&apos;: 4}
============================= test session starts ==============================
platform linux -- Python 3.5.6, pytest-3.10.1, py-1.7.0, pluggy-0.8.0
rootdir: /tmp/pytest-of-travis/pytest-0/test_run_all_tests7, inifile:
plugins: metadata-1.7.0, html-1.19.0, harvest-1.0.0, faulthandler-1.5.0, cov-2.6.0
collected 4 items

test_run_all_tests.py ....                                               [100%]

=========================== 4 passed in 0.03 seconds ===========================
</system-out></testcase><testcase classname="pytest_steps.tests.test_all" file="pytest_steps/tests/test_all.py" line="21" name="test_run_all_tests[test_docs_example_with_harvest.py]" time="0.4208493232727051"><system-out>
Testing that running pytest on file test_docs_example_with_harvest.py results in {&apos;skipped&apos;: 0, &apos;failed&apos;: 0, &apos;passed&apos;: 13}
============================= test session starts ==============================
platform linux -- Python 3.5.6, pytest-3.10.1, py-1.7.0, pluggy-0.8.0
rootdir: /tmp/pytest-of-travis/pytest-0/test_run_all_tests8, inifile:
plugins: metadata-1.7.0, html-1.19.0, harvest-1.0.0, faulthandler-1.5.0, cov-2.6.0
collected 13 items

test_run_all_tests.py .............                                      [100%]

=============================== warnings summary ===============================
test_run_all_tests.py::test_synthesis
  /home/travis/miniconda/envs/test-environment/lib/python3.5/site-packages/pandas/core/reshape/merge.py:544: UserWarning: merging between different levels can give an unintended result (1 levels on the left, 2 on the right)
    warnings.warn(msg, UserWarning)

-- Docs: https://docs.pytest.org/en/latest/warnings.html
==================== 13 passed, 1 warnings in 0.37 seconds =====================
</system-out></testcase><testcase classname="pytest_steps.tests.test_all" file="pytest_steps/tests/test_all.py" line="21" name="test_run_all_tests[test_steps_no_results.py]" time="0.07092809677124023"><system-out>
Testing that running pytest on file test_steps_no_results.py results in {&apos;skipped&apos;: 0, &apos;failed&apos;: 0, &apos;passed&apos;: 4}
============================= test session starts ==============================
platform linux -- Python 3.5.6, pytest-3.10.1, py-1.7.0, pluggy-0.8.0
rootdir: /tmp/pytest-of-travis/pytest-0/test_run_all_tests9, inifile:
plugins: metadata-1.7.0, html-1.19.0, harvest-1.0.0, faulthandler-1.5.0, cov-2.6.0
collected 4 items

test_run_all_tests.py ....                                               [100%]

=========================== 4 passed in 0.02 seconds ===========================
</system-out></testcase><testcase classname="pytest_steps.tests.test_all" file="pytest_steps/tests/test_all.py" line="21" name="test_run_all_tests[test_decorator.py]" time="0.07558989524841309"><system-out>
Testing that running pytest on file test_decorator.py results in {&apos;skipped&apos;: 0, &apos;failed&apos;: 0, &apos;passed&apos;: 4}
============================= test session starts ==============================
platform linux -- Python 3.5.6, pytest-3.10.1, py-1.7.0, pluggy-0.8.0
rootdir: /tmp/pytest-of-travis/pytest-0/test_run_all_tests10, inifile:
plugins: metadata-1.7.0, html-1.19.0, harvest-1.0.0, faulthandler-1.5.0, cov-2.6.0
collected 4 items

test_run_all_tests.py ....                                               [100%]

=========================== 4 passed in 0.03 seconds ===========================
</system-out></testcase><testcase classname="pytest_steps.tests.test_all" file="pytest_steps/tests/test_all.py" line="21" name="test_run_all_tests[test_steps_dependencies.py]" time="0.08784174919128418"><system-out>
Testing that running pytest on file test_steps_dependencies.py results in {&apos;skipped&apos;: 1, &apos;failed&apos;: 2, &apos;passed&apos;: 3}
============================= test session starts ==============================
platform linux -- Python 3.5.6, pytest-3.10.1, py-1.7.0, pluggy-0.8.0
rootdir: /tmp/pytest-of-travis/pytest-0/test_run_all_tests11, inifile:
plugins: metadata-1.7.0, html-1.19.0, harvest-1.0.0, faulthandler-1.5.0, cov-2.6.0
collected 6 items

test_run_all_tests.py .Fs.F.                                             [100%]

=================================== FAILURES ===================================
________________________ test_suite_no_results[step_b] _________________________

test_step = &lt;function step_b at 0x7f3e830afea0&gt;
request = &lt;FixtureRequest for &lt;Function &apos;test_suite_no_results[step_b]&apos;&gt;&gt;

    @test_steps(step_a, step_b, step_c)
    def test_suite_no_results(test_step, request):
        &quot;&quot;&quot; In this test suite, the last step will be skipped because the second step failed (and there is a dependency) &quot;&quot;&quot;
    
        # Execute the step
&gt;       test_step()

test_run_all_tests.py:37: 
_ _ _ _ _ _ _ _ _ _ _ _ _ _ _ _ _ _ _ _ _ _ _ _ _ _ _ _ _ _ _ _ _ _ _ _ _ _ _ _ 

    def step_b():
        &quot;&quot;&quot; Step a of the test &quot;&quot;&quot;
    
        # perform this step
        print(&quot;step b&quot;)
&gt;       assert False
E       assert False

test_run_all_tests.py:20: AssertionError
----------------------------- Captured stdout call -----------------------------
step b
_____________________________ test_suite_1[step_b] _____________________________

test_step = &apos;step_b&apos;

    @test_steps(&apos;step_a&apos;, &apos;step_b&apos;, &apos;step_c&apos;)
    def test_suite_1(test_step):
        &quot;&quot;&quot; In this test suite the last step can &quot;see&quot; the dependency so it is still executed ...&quot;&quot;&quot;
        # Execute the step according to name
        if test_step == &apos;step_a&apos;:
            step_a()
        elif test_step == &apos;step_b&apos;:
&gt;           step_b()

test_run_all_tests.py:47: 
_ _ _ _ _ _ _ _ _ _ _ _ _ _ _ _ _ _ _ _ _ _ _ _ _ _ _ _ _ _ _ _ _ _ _ _ _ _ _ _ 

    def step_b():
        &quot;&quot;&quot; Step a of the test &quot;&quot;&quot;
    
        # perform this step
        print(&quot;step b&quot;)
&gt;       assert False
E       assert False

test_run_all_tests.py:20: AssertionError
----------------------------- Captured stdout call -----------------------------
step b
================ 2 failed, 3 passed, 1 skipped in 0.04 seconds =================
</system-out></testcase><testcase classname="pytest_steps.tests.test_all" file="pytest_steps/tests/test_all.py" line="21" name="test_run_all_tests[test_stackoverflow2.py]" time="0.07044243812561035"><system-out>
Testing that running pytest on file test_stackoverflow2.py results in {&apos;skipped&apos;: 0, &apos;failed&apos;: 0, &apos;passed&apos;: 3}
============================= test session starts ==============================
platform linux -- Python 3.5.6, pytest-3.10.1, py-1.7.0, pluggy-0.8.0
rootdir: /tmp/pytest-of-travis/pytest-0/test_run_all_tests12, inifile:
plugins: metadata-1.7.0, html-1.19.0, harvest-1.0.0, faulthandler-1.5.0, cov-2.6.0
collected 3 items

test_run_all_tests.py ...                                                [100%]

=========================== 3 passed in 0.02 seconds ===========================
</system-out></testcase></testsuite>